<?xml version="1.0" ?>
<!-- =================================================================================== -->
<!-- |    This document was autogenerated by xacro from nanosaur.gazebo.xacro          | -->
<!-- |    EDITING THIS FILE BY HAND IS NOT RECOMMENDED                                 | -->
<!-- =================================================================================== -->
<robot name="nanosaur_gazebo">
  <material name="Black">
    <color rgba="0.1 0.1 0.1 1.0"/>
  </material>
  <material name="Green">
    <color rgba="0.0 0.8 0.0 1.0"/>
  </material>
  <material name="aluminum">
    <color rgba="0.5 0.5 0.5 1.0"/>
  </material>
  <material name="DarkGrey">
    <color rgba="0.3 0.3 0.3 1.0"/>
  </material>
  <material name="GunMetalGrey">
    <color rgba="0.46 0.5 0.56 1.0"/>
  </material>
  <material name="Gold">
    <color rgba="1 1 0.752941176470588 1"/>
  </material>
  <material name="zedm_mat">
    <color rgba="0 0 0 0.9"/>
  </material>
  <!-- Gazebo color reference https://bitbucket.org/osrf/gazebo/src/default/media/materials/scripts/gazebo.material?fileviewer=file-view-default
    Gazebo http://wiki.ros.org/simulator_gazebo/Tutorials/ListOfMaterials
    Ignition https://gazebosim.org/api/gazebo/3.7/migrationsdf.html
    -->
  <gazebo reference="base_front">
    <material>Gazebo/Green</material>
    <!-- Ignition color reference -->
    <visual>
      <material>
        <ambient>0.0 0.5 0.0 1.0</ambient>
        <diffuse>0.0 0.5 0.0 1.0</diffuse>
        <specular>0.0 0.5 0.0 1.0</specular>
      </material>
    </visual>
  </gazebo>
  <gazebo reference="base_rear">
    <material>Gazebo/Green</material>
    <!-- Ignition color reference -->
    <visual>
      <material>
        <ambient>0.0 0.5 0.0 1.0</ambient>
        <diffuse>0.0 0.5 0.0 1.0</diffuse>
        <specular>0.0 0.5 0.0 1.0</specular>
      </material>
    </visual>
  </gazebo>
  <gazebo reference="motor_board">
    <material>Gazebo/DarkGrey</material>
    <!-- Ignition color reference -->
    <visual>
      <material>
        <ambient>0.2 0.2 0.2 1.0</ambient>
        <diffuse>0.2 0.2 0.2 1.0</diffuse>
        <specular>0.2 0.2 0.2 1.0</specular>
      </material>
    </visual>
  </gazebo>
  <gazebo reference="power_bank">
    <material>Gazebo/DarkGrey</material>
    <!-- Ignition color reference -->
    <visual>
      <material>
        <ambient>0.2 0.2 0.2 1.0</ambient>
        <diffuse>0.2 0.2 0.2 1.0</diffuse>
        <specular>0.2 0.2 0.2 1.0</specular>
      </material>
    </visual>
  </gazebo>
  <gazebo reference="pb_holder">
    <material>Gazebo/Green</material>
    <!-- Ignition color reference -->
    <visual>
      <material>
        <ambient>0.0 0.5 0.0 1.0</ambient>
        <diffuse>0.0 0.5 0.0 1.0</diffuse>
        <specular>0.0 0.5 0.0 1.0</specular>
      </material>
    </visual>
  </gazebo>
  <gazebo reference="NVIDIA_jetson">
    <material>Gazebo/DarkGrey</material>
    <!-- Ignition color reference -->
    <visual>
      <material>
        <ambient>0.2 0.2 0.2 1.0</ambient>
        <diffuse>0.2 0.2 0.2 1.0</diffuse>
        <specular>0.2 0.2 0.2 1.0</specular>
      </material>
    </visual>
  </gazebo>
  <!-- nanosaur definition -->
  <link name="base_link"/>
  <joint name="base_front_joint" type="fixed">
    <origin rpy="0 0 0" xyz="0 0 0.03"/>
    <parent link="base_link"/>
    <child link="base_front"/>
  </joint>
  <link name="base_front">
    <inertial>
      <mass value="0.01"/>
      <origin rpy=" 0 0 0" xyz="0.053376 0 -0.007808"/>
      <inertia ixx="1.6666666666666668e-07" ixy="0" ixz="0" iyy="1.6666666666666668e-07" iyz="0" izz="1.6666666666666668e-07"/>
    </inertial>
    <visual>
      <geometry>
        <mesh filename="file:///home/suv/nanosaur_core/install/nanosaur_description/share/nanosaur_description/meshes/base_front.stl" scale="0.001 0.001 0.001"/>
      </geometry>
      <material name="Green"/>
    </visual>
  </link>
  <joint name="base_rear_joint" type="fixed">
    <origin rpy="0 0 0" xyz="0 0 0.03"/>
    <parent link="base_link"/>
    <child link="base_rear"/>
  </joint>
  <link name="base_rear">
    <inertial>
      <mass value="0.01"/>
      <origin rpy=" 0 0 0" xyz="0 0 0"/>
      <inertia ixx="1.6666666666666668e-07" ixy="0" ixz="0" iyy="1.6666666666666668e-07" iyz="0" izz="1.6666666666666668e-07"/>
    </inertial>
    <visual>
      <geometry>
        <mesh filename="file:///home/suv/nanosaur_core/install/nanosaur_description/share/nanosaur_description/meshes/base_rear.stl" scale="0.001 0.001 0.001"/>
      </geometry>
      <material name="Green"/>
    </visual>
    <collision>
      <origin rpy="0 0 0" xyz="0 0 -0.01"/>
      <geometry>
        <box size="0.12 0.07 0.03"/>
      </geometry>
      <material name="Green"/>
    </collision>
  </link>
  <joint name="motor_board_joint" type="fixed">
    <origin rpy="0 0.9599302777777777 0" xyz="0.055 0 0.005"/>
    <parent link="base_front"/>
    <child link="motor_board"/>
  </joint>
  <link name="motor_board">
    <inertial>
      <mass value="0.01"/>
      <origin rpy=" 0 0 0" xyz="0 0 0"/>
      <inertia ixx="1.6666666666666668e-07" ixy="0" ixz="0" iyy="1.6666666666666668e-07" iyz="0" izz="1.6666666666666668e-07"/>
    </inertial>
    <visual>
      <geometry>
        <mesh filename="file:///home/suv/nanosaur_core/install/nanosaur_description/share/nanosaur_description/meshes/parts/motor_board.stl"/>
      </geometry>
      <material name="GunMetalGrey"/>
    </visual>
  </link>
  <joint name="power_bank_joint" type="fixed">
    <origin rpy="0 0 0" xyz="0.0 0 0.0"/>
    <parent link="base_rear"/>
    <child link="power_bank"/>
  </joint>
  <link name="power_bank">
    <inertial>
      <mass value="0.01"/>
      <origin rpy=" 0 0 0" xyz="0 0 0"/>
      <inertia ixx="1.6666666666666668e-07" ixy="0" ixz="0" iyy="1.6666666666666668e-07" iyz="0" izz="1.6666666666666668e-07"/>
    </inertial>
    <visual>
      <origin rpy="0 0 3.14159" xyz="0.0 0 -0.0115"/>
      <geometry>
        <mesh filename="file:///home/suv/nanosaur_core/install/nanosaur_description/share/nanosaur_description/meshes/parts/power_bank.stl"/>
      </geometry>
      <material name="DarkGrey"/>
    </visual>
  </link>
  <joint name="pb_holder_joint" type="fixed">
    <origin rpy="0 0 0" xyz="-0.0545 0 -0.0061"/>
    <parent link="base_rear"/>
    <child link="pb_holder"/>
  </joint>
  <link name="pb_holder">
    <inertial>
      <mass value="0.01"/>
      <origin rpy=" 0 0 0" xyz="0 0 0"/>
      <inertia ixx="1.6666666666666668e-07" ixy="0" ixz="0" iyy="1.6666666666666668e-07" iyz="0" izz="1.6666666666666668e-07"/>
    </inertial>
    <visual>
      <origin rpy="0 0 0" xyz="0.0 0 0"/>
      <geometry>
        <mesh filename="file:///home/suv/nanosaur_core/install/nanosaur_description/share/nanosaur_description/meshes/pb_holder.stl" scale="0.001 0.001 0.001"/>
      </geometry>
      <material name="Green"/>
    </visual>
  </link>
  <joint name="NVIDIA_jetson_joint" type="fixed">
    <origin rpy="0 0 0" xyz="0 0 0"/>
    <parent link="base_rear"/>
    <child link="NVIDIA_jetson"/>
  </joint>
  <link name="NVIDIA_jetson">
    <inertial>
      <mass value="0.01"/>
      <origin rpy=" 0 0 0" xyz="0 0 0"/>
      <inertia ixx="1.6666666666666668e-07" ixy="0" ixz="0" iyy="1.6666666666666668e-07" iyz="0" izz="1.6666666666666668e-07"/>
    </inertial>
    <visual>
      <origin rpy="0 0 3.14159" xyz="0.039 0.022 0.005"/>
      <geometry>
        <mesh filename="file:///home/suv/nanosaur_core/install/nanosaur_description/share/nanosaur_description/meshes/parts/NVIDIA_jetson_nano_4gb.stl"/>
      </geometry>
      <material name="DarkGrey"/>
    </visual>
  </link>
  <joint name="sprocket_left_joint" type="continuous">
    <origin rpy="-1.570795 0 0" xyz="0.0 0.043 0.015"/>
    <parent link="base_link"/>
    <child link="sprocket_left"/>
    <axis xyz="0 0 1"/>
  </joint>
  <link name="sprocket_left">
    <inertial>
      <mass value="0.01"/>
      <origin rpy=" 0 0 0" xyz="0 0 0"/>
      <inertia ixx="1.6666666666666668e-07" ixy="0" ixz="0" iyy="1.6666666666666668e-07" iyz="0" izz="1.6666666666666668e-07"/>
    </inertial>
    <visual>
      <origin rpy="0 0 0" xyz="0 0 0"/>
      <geometry>
        <mesh filename="file:///home/suv/nanosaur_core/install/nanosaur_description/share/nanosaur_description/meshes/sprocket.stl" scale="0.001 0.001 0.001"/>
      </geometry>
      <material name="Black"/>
    </visual>
    <!-- Collision cylinder -->
    <collision>
      <origin rpy="0 0 0" xyz="0 0 0"/>
      <geometry>
        <cylinder length="0.015" radius="0.015"/>
      </geometry>
      <material name="Black"/>
    </collision>
  </link>
  <gazebo reference="sprocket_left">
    <kp>10000000</kp>
    <kd>10000000</kd>
    <mu1>10000000</mu1>
    <mu2>10000000</mu2>
    <material>Gazebo/Blue</material>
    <!-- Ignition color reference -->
    <visual>
      <material>
        <ambient>0.0 0.0 0.5 1.0</ambient>
        <diffuse>0.0 0.0 0.5 1.0</diffuse>
        <specular>0.0 0.0 0.5 1.0</specular>
      </material>
    </visual>
  </gazebo>
  <joint name="motor_left_joint" type="fixed">
    <origin rpy="-1.570795 0 0" xyz="0.053 0.043 0.015"/>
    <parent link="base_link"/>
    <child link="motor_left"/>
  </joint>
  <link name="motor_left">
    <visual>
      <origin rpy="0 0 -1.570795" xyz="0 0 -0.031"/>
      <geometry>
        <mesh filename="file:///home/suv/nanosaur_core/install/nanosaur_description/share/nanosaur_description/meshes/parts/Pololu-Micro-Metal-Gearmotor.stl"/>
      </geometry>
      <material name="Gold"/>
    </visual>
  </link>
  <gazebo reference="motor_left">
    <material>Gazebo/Gold</material>
    <!-- Ignition color reference -->
    <visual>
      <material>
        <ambient>0.9 0.7 0.0 1.0</ambient>
        <diffuse>0.9 0.7 0.0 1.0</diffuse>
        <specular>0.9 0.7 0.0 1.0</specular>
      </material>
    </visual>
  </gazebo>
  <joint name="wheel_left_joint" type="continuous">
    <origin rpy="0 0 0" xyz="-0.099 0 0"/>
    <parent link="motor_left"/>
    <child link="wheel_left"/>
    <axis xyz="0 0 1"/>
    <mimic joint="sprocket_left_joint" multiplier="1" offset="0"/>
  </joint>
  <link name="wheel_left">
    <inertial>
      <mass value="0.01"/>
      <origin rpy=" 0 0 0" xyz="0 0 0"/>
      <inertia ixx="1.6666666666666668e-07" ixy="0" ixz="0" iyy="1.6666666666666668e-07" iyz="0" izz="1.6666666666666668e-07"/>
    </inertial>
    <visual>
      <origin rpy="0 0 0" xyz="0 0 0"/>
      <geometry>
        <mesh filename="file:///home/suv/nanosaur_core/install/nanosaur_description/share/nanosaur_description/meshes/wheel.stl" scale="0.001 0.001 0.001"/>
      </geometry>
      <material name="Black"/>
    </visual>
    <!-- Collision cylinder -->
    <collision>
      <origin rpy="0 0 0" xyz="0 0 0"/>
      <geometry>
        <cylinder length="0.015" radius="0.015"/>
      </geometry>
      <material name="Black"/>
    </collision>
  </link>
  <gazebo reference="wheel_left">
    <kp>10000000</kp>
    <kd>10000000</kd>
    <mu1>0</mu1>
    <mu2>0</mu2>
    <material>Gazebo/Red</material>
    <!-- Ignition color reference -->
    <visual>
      <material>
        <ambient>0.5 0.0 0.0 1.0</ambient>
        <diffuse>0.5 0.0 0.0 1.0</diffuse>
        <specular>0.5 0.0 0.0 1.0</specular>
      </material>
    </visual>
  </gazebo>
  <joint name="front_wheel_left_joint" type="continuous">
    <origin rpy="0 0 0" xyz="0 0 0"/>
    <parent link="motor_left"/>
    <child link="front_wheel_left"/>
    <axis xyz="0 0 1"/>
    <mimic joint="sprocket_left_joint" multiplier="1" offset="0"/>
  </joint>
  <link name="front_wheel_left">
    <inertial>
      <mass value="0.01"/>
      <origin rpy=" 0 0 0" xyz="0 0 0"/>
      <inertia ixx="1.6666666666666668e-07" ixy="0" ixz="0" iyy="1.6666666666666668e-07" iyz="0" izz="1.6666666666666668e-07"/>
    </inertial>
    <visual>
      <origin rpy="0 0 0" xyz="0 0 0"/>
      <geometry>
        <mesh filename="file:///home/suv/nanosaur_core/install/nanosaur_description/share/nanosaur_description/meshes/wheel.stl" scale="0.001 0.001 0.001"/>
      </geometry>
      <material name="Black"/>
    </visual>
    <!-- Collision cylinder -->
    <collision>
      <origin rpy="0 0 0" xyz="0 0 0"/>
      <geometry>
        <cylinder length="0.015" radius="0.015"/>
      </geometry>
      <material name="Black"/>
    </collision>
  </link>
  <gazebo reference="front_wheel_left">
    <kp>10000000</kp>
    <kd>10000000</kd>
    <mu1>0</mu1>
    <mu2>0</mu2>
    <material>Gazebo/Green</material>
    <!-- Ignition color reference -->
    <visual>
      <material>
        <ambient>0.0 0.5 0.0 1.0</ambient>
        <diffuse>0.0 0.5 0.0 1.0</diffuse>
        <specular>0.0 0.5 0.0 1.0</specular>
      </material>
    </visual>
  </gazebo>
  <joint name="track_left_joint" type="fixed">
    <origin rpy="0 0 0" xyz="-0.049 0 0"/>
    <parent link="motor_left"/>
    <child link="track_left"/>
  </joint>
  <link name="track_left">
    <inertial>
      <mass value="0.01"/>
      <origin rpy=" 0 0 0" xyz="0 0 0"/>
      <inertia ixx="1.6666666666666668e-07" ixy="0" ixz="0" iyy="1.6666666666666668e-07" iyz="0" izz="1.6666666666666668e-07"/>
    </inertial>
    <visual>
      <origin rpy="1.570795 0 0" xyz="0 0 0"/>
      <geometry>
        <mesh filename="file:///home/suv/nanosaur_core/install/nanosaur_description/share/nanosaur_description/meshes/track.stl" scale="0.001 0.001 0.001"/>
      </geometry>
      <material name="Black"/>
    </visual>
  </link>
  <gazebo reference="track_left">
    <material>Gazebo/Black</material>
    <!-- Ignition color reference -->
    <visual>
      <material>
        <ambient>0.01 0.01 0.01 1.0</ambient>
        <diffuse>0.01 0.01 0.01 1.0</diffuse>
        <specular>0.01 0.01 0.01 1.0</specular>
      </material>
    </visual>
  </gazebo>
  <joint name="slider_left_joint" type="fixed">
    <parent link="track_left"/>
    <child link="slider_left"/>
  </joint>
  <link name="slider_left">
    <inertial>
      <mass value="0.01"/>
      <origin rpy=" 0 0 0" xyz="0 0 0"/>
      <inertia ixx="1.6666666666666668e-07" ixy="0" ixz="0" iyy="1.6666666666666668e-07" iyz="0" izz="1.6666666666666668e-07"/>
    </inertial>
    <visual>
      <origin rpy="0 0 0" xyz="0 0 0.008"/>
      <geometry>
        <mesh filename="file:///home/suv/nanosaur_core/install/nanosaur_description/share/nanosaur_description/meshes/slider.stl" scale="0.001 0.001 0.001"/>
      </geometry>
      <material name="Green"/>
    </visual>
  </link>
  <gazebo reference="slider_left">
    <material>Gazebo/Green</material>
    <!-- Ignition color reference -->
    <visual>
      <material>
        <ambient>0.0 0.5 0.0 1.0</ambient>
        <diffuse>0.0 0.5 0.0 1.0</diffuse>
        <specular>0.0 0.5 0.0 1.0</specular>
      </material>
    </visual>
  </gazebo>
  <joint name="sprocket_right_joint" type="continuous">
    <origin rpy="1.570795 0 0" xyz="0.0 -0.043 0.015"/>
    <parent link="base_link"/>
    <child link="sprocket_right"/>
    <axis xyz="0 0 -1"/>
  </joint>
  <link name="sprocket_right">
    <inertial>
      <mass value="0.01"/>
      <origin rpy=" 0 0 0" xyz="0 0 0"/>
      <inertia ixx="1.6666666666666668e-07" ixy="0" ixz="0" iyy="1.6666666666666668e-07" iyz="0" izz="1.6666666666666668e-07"/>
    </inertial>
    <visual>
      <origin rpy="0 0 0" xyz="0 0 0"/>
      <geometry>
        <mesh filename="file:///home/suv/nanosaur_core/install/nanosaur_description/share/nanosaur_description/meshes/sprocket.stl" scale="0.001 0.001 0.001"/>
      </geometry>
      <material name="Black"/>
    </visual>
    <!-- Collision cylinder -->
    <collision>
      <origin rpy="0 0 0" xyz="0 0 0"/>
      <geometry>
        <cylinder length="0.015" radius="0.015"/>
      </geometry>
      <material name="Black"/>
    </collision>
  </link>
  <gazebo reference="sprocket_right">
    <kp>10000000</kp>
    <kd>10000000</kd>
    <mu1>10000000</mu1>
    <mu2>10000000</mu2>
    <material>Gazebo/Blue</material>
    <!-- Ignition color reference -->
    <visual>
      <material>
        <ambient>0.0 0.0 0.5 1.0</ambient>
        <diffuse>0.0 0.0 0.5 1.0</diffuse>
        <specular>0.0 0.0 0.5 1.0</specular>
      </material>
    </visual>
  </gazebo>
  <joint name="motor_right_joint" type="fixed">
    <origin rpy="1.570795 0 0" xyz="0.053 -0.043 0.015"/>
    <parent link="base_link"/>
    <child link="motor_right"/>
  </joint>
  <link name="motor_right">
    <visual>
      <origin rpy="0 0 -1.570795" xyz="0 0 -0.031"/>
      <geometry>
        <mesh filename="file:///home/suv/nanosaur_core/install/nanosaur_description/share/nanosaur_description/meshes/parts/Pololu-Micro-Metal-Gearmotor.stl"/>
      </geometry>
      <material name="Gold"/>
    </visual>
  </link>
  <gazebo reference="motor_right">
    <material>Gazebo/Gold</material>
    <!-- Ignition color reference -->
    <visual>
      <material>
        <ambient>0.9 0.7 0.0 1.0</ambient>
        <diffuse>0.9 0.7 0.0 1.0</diffuse>
        <specular>0.9 0.7 0.0 1.0</specular>
      </material>
    </visual>
  </gazebo>
  <joint name="wheel_right_joint" type="continuous">
    <origin rpy="0 0 0" xyz="-0.099 0 0"/>
    <parent link="motor_right"/>
    <child link="wheel_right"/>
    <axis xyz="0 0 -1"/>
    <mimic joint="sprocket_right_joint" multiplier="1" offset="0"/>
  </joint>
  <link name="wheel_right">
    <inertial>
      <mass value="0.01"/>
      <origin rpy=" 0 0 0" xyz="0 0 0"/>
      <inertia ixx="1.6666666666666668e-07" ixy="0" ixz="0" iyy="1.6666666666666668e-07" iyz="0" izz="1.6666666666666668e-07"/>
    </inertial>
    <visual>
      <origin rpy="0 0 0" xyz="0 0 0"/>
      <geometry>
        <mesh filename="file:///home/suv/nanosaur_core/install/nanosaur_description/share/nanosaur_description/meshes/wheel.stl" scale="0.001 0.001 0.001"/>
      </geometry>
      <material name="Black"/>
    </visual>
    <!-- Collision cylinder -->
    <collision>
      <origin rpy="0 0 0" xyz="0 0 0"/>
      <geometry>
        <cylinder length="0.015" radius="0.015"/>
      </geometry>
      <material name="Black"/>
    </collision>
  </link>
  <gazebo reference="wheel_right">
    <kp>10000000</kp>
    <kd>10000000</kd>
    <mu1>0</mu1>
    <mu2>0</mu2>
    <material>Gazebo/Red</material>
    <!-- Ignition color reference -->
    <visual>
      <material>
        <ambient>0.5 0.0 0.0 1.0</ambient>
        <diffuse>0.5 0.0 0.0 1.0</diffuse>
        <specular>0.5 0.0 0.0 1.0</specular>
      </material>
    </visual>
  </gazebo>
  <joint name="front_wheel_right_joint" type="continuous">
    <origin rpy="0 0 0" xyz="0 0 0"/>
    <parent link="motor_right"/>
    <child link="front_wheel_right"/>
    <axis xyz="0 0 -1"/>
    <mimic joint="sprocket_right_joint" multiplier="1" offset="0"/>
  </joint>
  <link name="front_wheel_right">
    <inertial>
      <mass value="0.01"/>
      <origin rpy=" 0 0 0" xyz="0 0 0"/>
      <inertia ixx="1.6666666666666668e-07" ixy="0" ixz="0" iyy="1.6666666666666668e-07" iyz="0" izz="1.6666666666666668e-07"/>
    </inertial>
    <visual>
      <origin rpy="0 0 0" xyz="0 0 0"/>
      <geometry>
        <mesh filename="file:///home/suv/nanosaur_core/install/nanosaur_description/share/nanosaur_description/meshes/wheel.stl" scale="0.001 0.001 0.001"/>
      </geometry>
      <material name="Black"/>
    </visual>
    <!-- Collision cylinder -->
    <collision>
      <origin rpy="0 0 0" xyz="0 0 0"/>
      <geometry>
        <cylinder length="0.015" radius="0.015"/>
      </geometry>
      <material name="Black"/>
    </collision>
  </link>
  <gazebo reference="front_wheel_right">
    <kp>10000000</kp>
    <kd>10000000</kd>
    <mu1>0</mu1>
    <mu2>0</mu2>
    <material>Gazebo/Green</material>
    <!-- Ignition color reference -->
    <visual>
      <material>
        <ambient>0.0 0.5 0.0 1.0</ambient>
        <diffuse>0.0 0.5 0.0 1.0</diffuse>
        <specular>0.0 0.5 0.0 1.0</specular>
      </material>
    </visual>
  </gazebo>
  <joint name="track_right_joint" type="fixed">
    <origin rpy="0 0 0" xyz="-0.049 0 0"/>
    <parent link="motor_right"/>
    <child link="track_right"/>
  </joint>
  <link name="track_right">
    <inertial>
      <mass value="0.01"/>
      <origin rpy=" 0 0 0" xyz="0 0 0"/>
      <inertia ixx="1.6666666666666668e-07" ixy="0" ixz="0" iyy="1.6666666666666668e-07" iyz="0" izz="1.6666666666666668e-07"/>
    </inertial>
    <visual>
      <origin rpy="1.570795 0 0" xyz="0 0 0"/>
      <geometry>
        <mesh filename="file:///home/suv/nanosaur_core/install/nanosaur_description/share/nanosaur_description/meshes/track.stl" scale="0.001 0.001 0.001"/>
      </geometry>
      <material name="Black"/>
    </visual>
  </link>
  <gazebo reference="track_right">
    <material>Gazebo/Black</material>
    <!-- Ignition color reference -->
    <visual>
      <material>
        <ambient>0.01 0.01 0.01 1.0</ambient>
        <diffuse>0.01 0.01 0.01 1.0</diffuse>
        <specular>0.01 0.01 0.01 1.0</specular>
      </material>
    </visual>
  </gazebo>
  <joint name="slider_right_joint" type="fixed">
    <parent link="track_right"/>
    <child link="slider_right"/>
  </joint>
  <link name="slider_right">
    <inertial>
      <mass value="0.01"/>
      <origin rpy=" 0 0 0" xyz="0 0 0"/>
      <inertia ixx="1.6666666666666668e-07" ixy="0" ixz="0" iyy="1.6666666666666668e-07" iyz="0" izz="1.6666666666666668e-07"/>
    </inertial>
    <visual>
      <origin rpy="0 0 0" xyz="0 0 0.008"/>
      <geometry>
        <mesh filename="file:///home/suv/nanosaur_core/install/nanosaur_description/share/nanosaur_description/meshes/slider.stl" scale="0.001 0.001 0.001"/>
      </geometry>
      <material name="Green"/>
    </visual>
  </link>
  <gazebo reference="slider_right">
    <material>Gazebo/Green</material>
    <!-- Ignition color reference -->
    <visual>
      <material>
        <ambient>0.0 0.5 0.0 1.0</ambient>
        <diffuse>0.0 0.5 0.0 1.0</diffuse>
        <specular>0.0 0.5 0.0 1.0</specular>
      </material>
    </visual>
  </gazebo>
  <gazebo reference="flap_bottom">
    <material>Gazebo/Green</material>
    <!-- Ignition color reference -->
    <visual>
      <material>
        <ambient>0.0 0.5 0.0 1.0</ambient>
        <diffuse>0.0 0.5 0.0 1.0</diffuse>
        <specular>0.0 0.5 0.0 1.0</specular>
      </material>
    </visual>
  </gazebo>
  <gazebo reference="flap_top">
    <material>Gazebo/Green</material>
    <!-- Ignition color reference -->
    <visual>
      <material>
        <ambient>0.0 0.5 0.0 1.0</ambient>
        <diffuse>0.0 0.5 0.0 1.0</diffuse>
        <specular>0.0 0.5 0.0 1.0</specular>
      </material>
    </visual>
  </gazebo>
  <gazebo reference="board_expansion">
    <material>Gazebo/DarkGrey</material>
    <!-- Ignition color reference -->
    <visual>
      <material>
        <ambient>0.5 0.5 0.5 1.0</ambient>
        <diffuse>0.5 0.5 0.5 1.0</diffuse>
        <specular>0.5 0.5 0.5 1.0</specular>
      </material>
    </visual>
  </gazebo>
  <joint name="flap_bottom_joint" type="fixed">
    <origin rpy="0 0 0" xyz="-0.05 0 0"/>
    <parent link="base_rear"/>
    <child link="flap_bottom"/>
  </joint>
  <link name="flap_bottom">
    <inertial>
      <mass value="0.01"/>
      <origin rpy=" 0 0 0" xyz="0 0 0"/>
      <inertia ixx="1.6666666666666668e-07" ixy="0" ixz="0" iyy="1.6666666666666668e-07" iyz="0" izz="1.6666666666666668e-07"/>
    </inertial>
    <visual>
      <!--<origin xyz="-0.0161 0 0.009" rpy="0 0 0" />-->
      <origin rpy="0 0 0" xyz="0.0068 0 0.0175"/>
      <geometry>
        <mesh filename="file:///home/suv/nanosaur_core/install/nanosaur_description/share/nanosaur_description/meshes/flap_bottom.stl" scale="0.001 0.001 0.001"/>
      </geometry>
      <material name="Green"/>
    </visual>
  </link>
  <joint name="flap_top_joint" type="fixed">
    <parent link="flap_bottom"/>
    <child link="flap_top"/>
  </joint>
  <link name="flap_top">
    <inertial>
      <mass value="0.01"/>
      <origin rpy=" 0 0 0" xyz="0 0 0"/>
      <inertia ixx="1.6666666666666668e-07" ixy="0" ixz="0" iyy="1.6666666666666668e-07" iyz="0" izz="1.6666666666666668e-07"/>
    </inertial>
    <visual>
      <!--<origin xyz="-0.0161 0 0.009" rpy="0 0 0" />-->
      <origin rpy="0 0 0" xyz="0.0068 0 0.0175"/>
      <geometry>
        <mesh filename="file:///home/suv/nanosaur_core/install/nanosaur_description/share/nanosaur_description/meshes/flap_top.stl" scale="0.001 0.001 0.001"/>
      </geometry>
      <material name="Green"/>
    </visual>
  </link>
  <joint name="board_expansion_joint" type="fixed">
    <parent link="flap_bottom"/>
    <child link="board_expansion"/>
  </joint>
  <link name="board_expansion">
    <inertial>
      <mass value="0.01"/>
      <origin rpy=" 0 0 0" xyz="0 0 0"/>
      <inertia ixx="1.6666666666666668e-07" ixy="0" ixz="0" iyy="1.6666666666666668e-07" iyz="0" izz="1.6666666666666668e-07"/>
    </inertial>
    <visual>
      <!--<origin xyz="-0.0017 0 0.019" rpy="0 0 0" />-->
      <origin rpy="0 0 0" xyz="-0.002 0.0005 0.017"/>
      <geometry>
        <mesh filename="file:///home/suv/nanosaur_core/install/nanosaur_description/share/nanosaur_description/meshes/parts/nanosaur-exp-board.stl"/>
      </geometry>
      <material name="GunMetalGrey"/>
    </visual>
  </link>
  <gazebo reference="cover">
    <material>Gazebo/Green</material>
    <!-- Ignition color reference -->
    <visual>
      <material>
        <ambient>0.0 0.5 0.0 1.0</ambient>
        <diffuse>0.0 0.5 0.0 1.0</diffuse>
        <specular>0.0 0.5 0.0 1.0</specular>
      </material>
    </visual>
  </gazebo>
  <gazebo reference="display_left">
    <material>Gazebo/Black</material>
  </gazebo>
  <gazebo reference="display_right">
    <material>Gazebo/Black</material>
  </gazebo>
  <gazebo reference="camera_board">
    <material>Gazebo/Grey</material>
    <!-- Ignition color reference -->
    <visual>
      <material>
        <ambient>0.2 0.2 0.2 1.0</ambient>
        <diffuse>0.2 0.2 0.2 1.0</diffuse>
        <specular>0.2 0.2 0.2 1.0</specular>
      </material>
    </visual>
  </gazebo>
  <joint name="cover_joint" type="fixed">
    <origin rpy="0 0 0" xyz="0.06 0 -0.026"/>
    <parent link="base_front"/>
    <child link="cover"/>
  </joint>
  <link name="cover">
    <inertial>
      <mass value="0.01"/>
      <origin rpy=" 0 0 0" xyz="0 0 0"/>
      <inertia ixx="1.6666666666666668e-07" ixy="0" ixz="0" iyy="1.6666666666666668e-07" iyz="0" izz="1.6666666666666668e-07"/>
    </inertial>
    <visual>
      <geometry>
        <mesh filename="file:///home/suv/nanosaur_core/install/nanosaur_description/share/nanosaur_description/meshes/cover-fe.stl" scale="0.001 0.001 0.001"/>
      </geometry>
      <material name="Green"/>
    </visual>
    <!-- Collision cylinder -->
    <collision>
      <origin rpy="1.570795 1.570795 0" xyz="0.003 0 0.03"/>
      <geometry>
        <cylinder length="0.07" radius="0.028"/>
      </geometry>
      <material name="Green"/>
    </collision>
  </link>
  <joint name="display_left_joint" type="fixed">
    <origin rpy="0 0.4014253888888888 0" xyz="-0.024 0.0242 0.060"/>
    <parent link="cover"/>
    <child link="display_left"/>
  </joint>
  <link name="display_left">
    <inertial>
      <mass value="0.01"/>
      <origin rpy=" 0 0 0" xyz="0 0 0"/>
      <inertia ixx="1.6666666666666668e-07" ixy="0" ixz="0" iyy="1.6666666666666668e-07" iyz="0" izz="1.6666666666666668e-07"/>
    </inertial>
    <visual>
      <origin rpy="0 0 1.570795" xyz="0 0 0"/>
      <geometry>
        <mesh filename="file:///home/suv/nanosaur_core/install/nanosaur_description/share/nanosaur_description/meshes/parts/OLED_Module.stl"/>
      </geometry>
      <material name="Black"/>
    </visual>
  </link>
  <joint name="display_right_joint" type="fixed">
    <origin rpy="0 0.4014253888888888 0" xyz="-0.024 -0.0242 0.060"/>
    <parent link="cover"/>
    <child link="display_right"/>
  </joint>
  <link name="display_right">
    <inertial>
      <mass value="0.01"/>
      <origin rpy=" 0 0 0" xyz="0 0 0"/>
      <inertia ixx="1.6666666666666668e-07" ixy="0" ixz="0" iyy="1.6666666666666668e-07" iyz="0" izz="1.6666666666666668e-07"/>
    </inertial>
    <visual>
      <origin rpy="0 0 1.570795" xyz="0 0 0"/>
      <geometry>
        <mesh filename="file:///home/suv/nanosaur_core/install/nanosaur_description/share/nanosaur_description/meshes/parts/OLED_Module.stl"/>
      </geometry>
      <material name="Black"/>
    </visual>
  </link>
  <joint name="camera_joint" type="fixed">
    <origin rpy="0 1.483528611111111 0" xyz="0.0142 0 0.0310"/>
    <parent link="cover"/>
    <child link="camera_board"/>
  </joint>
  <link name="camera_board">
    <inertial>
      <mass value="0.01"/>
      <origin rpy=" 0 0 0" xyz="0 0 0"/>
      <inertia ixx="1.6666666666666668e-07" ixy="0" ixz="0" iyy="1.6666666666666668e-07" iyz="0" izz="1.6666666666666668e-07"/>
    </inertial>
    <visual>
      <origin rpy="1.570795 0 -1.570795" xyz="-0.0039 0 -0.001"/>
      <geometry>
        <mesh filename="file:///home/suv/nanosaur_core/install/nanosaur_description/share/nanosaur_description/meshes/parts/fisheye_camera.dae"/>
      </geometry>
    </visual>
  </link>
  <joint name="camera_optical_joint" type="fixed">
    <origin rpy="0 0 -1.570795" xyz="0 0 0.005"/>
    <parent link="camera_board"/>
    <child link="camera_optical_frame"/>
  </joint>
  <link name="camera_optical_frame"/>
  <gazebo>
    <plugin filename="libgazebo_ros_diff_drive.so" name="skid_steer_drive_controller">
      <ros>
        <namespace>/nanosaur</namespace>
        <argument>--ros-args --remap /cmd_vel:=cmd_vel</argument>
        <argument>--ros-args --remap /odom:=odom</argument>
      </ros>
      <!-- Plugin update rate in Hz -->
      <update_rate>100.0</update_rate>
      <num_wheel_pairs>2</num_wheel_pairs>
      <!-- Name of left joint, defaults to `left_joint` -->
      <left_joint>sprocket_left_joint</left_joint>
      <left_joint>wheel_left_joint</left_joint>
      <!-- Name of right joint, defaults to `right_joint` -->
      <right_joint>sprocket_right_joint</right_joint>
      <right_joint>wheel_right_joint</right_joint>
      <!-- The distance from the center of one wheel to the other, in meters, defaults to 0.34 m -->
      <wheel_separation>0.4</wheel_separation>
      <!-- Diameter of the wheels, in meters, defaults to 0.15 m -->
      <wheel_diameter>0.03</wheel_diameter>
      <!-- Wheel acceleration, in rad/s^2, defaults to 0.0 rad/s^2 -->
      <wheel_acceleration>0.0</wheel_acceleration>
      <!-- Maximum torque which the wheels can produce, in Nm, defaults to 5 Nm -->
      <max_wheel_torque>15</max_wheel_torque>
      <!-- Odometry frame, defaults to `odom` -->
      <odometry_frame>odom</odometry_frame>
      <!-- Robot frame to calculate odometry from, defaults to `base_footprint` -->
      <robot_base_frame>base_link</robot_base_frame>
      <!-- Set to true to publish transforms for the odometry, defaults to true -->
      <publish_odom>true</publish_odom>
      <publish_odom_tf>False</publish_odom_tf>
      <!-- Set to true to publish transforms for the wheel links, defaults to false -->
      <publish_wheel_tf>true</publish_wheel_tf>
      <!-- Odometry source, 0 for ENCODER, 1 for WORLD, defaults to WORLD -->
      <odometry_source>1</odometry_source>
      <!-- Set to true to publish sensor_msgs/JointState on /joint_states for the wheel joints, defaults to false -->
      <publis_wheel_joint_state>false</publis_wheel_joint_state>
    </plugin>
  </gazebo>
  <link name="camera_camera_link">
    <visual>
      <origin rpy="0 0 0" xyz="0 0 0"/>
      <geometry>
        <box size="0.02 0.01 0.01"/>
      </geometry>
    </visual>
  </link>
  <joint name="camera_camera_link_joint" type="fixed">
    <origin rpy="0 -1.570795 0" xyz="0 0 0"/>
    <parent link="camera_board"/>
    <child link="camera_camera_link"/>
  </joint>
  <link name="camera_camera_link_frame">
    </link>
  <joint name="camera_camera_frame_joint" type="fixed">
    <origin rpy="0 0 0" xyz="0.02 0 0"/>
    <parent link="camera_camera_link"/>
    <child link="camera_camera_link_frame"/>
    <axis xyz="0 0 0"/>
  </joint>
  <gazebo reference="camera_camera_link_frame">
    <sensor name="camera" type="wideanglecamera">
      <camera>
        <horizontal_fov>6.283</horizontal_fov>
        <image>
          <width>320</width>
          <height>240</height>
        </image>
        <clip>
          <near>0.1</near>
          <far>100</far>
        </clip>
        <!-- A new section named `lens`. -->
        <lens>
          <!-- type element is mandatory -->
          <type>custom</type>
          <!-- manually defined mapping function r = c1*f*fun(theta/c2 + c3) -->
          <!-- More information here https://en.wikipedia.org/wiki/Fisheye_lens#Mapping_function -->
          <custom_function>
            <c1>1.05</c1>
            <!-- linear scaling -->
            <c2>4</c2>
            <!-- angle scaling -->
            <f>1.0</f>
            <!-- one more scaling parameter -->
            <fun>tan</fun>
            <!-- one of sin,tan,id -->
          </custom_function>
          <!-- if it is set to `true` your horizontal FOV will ramain as defined -->
          <!-- othervise it depends on lens type and custom function, if there is one -->
          <scale_to_hfov>true</scale_to_hfov>
          <!-- clip everything that is outside of this angle -->
          <cutoff_angle>3.1415</cutoff_angle>
          <!-- resolution of the cubemap texture, the highter it is - the sharper is your image -->
          <env_texture_size>512</env_texture_size>
        </lens>
        <always_on>1</always_on>
        <update_rate>30</update_rate>
      </camera>
      <plugin filename="libgazebo_ros_camera.so" name="camera_controller">
        <cameraName>camera</cameraName>
        <imageTopicName>image_raw</imageTopicName>
        <cameraInfoTopicName>camera_info</cameraInfoTopicName>
        <frameName>camera_camera_link_frame</frameName>
        <hackBaseline>0.07</hackBaseline>
      </plugin>
    </sensor>
  </gazebo>
</robot>
