<sdf version='1.7'>
  <world name='default'>
    <light name='sun' type='directional'>
      <cast_shadows>1</cast_shadows>
      <pose>0 0 10 0 -0 0</pose>
      <diffuse>0.8 0.8 0.8 1</diffuse>
      <specular>0.2 0.2 0.2 1</specular>
      <attenuation>
        <range>1000</range>
        <constant>0.9</constant>
        <linear>0.01</linear>
        <quadratic>0.001</quadratic>
      </attenuation>
      <direction>-0.5 0.1 -0.9</direction>
      <spot>
        <inner_angle>0</inner_angle>
        <outer_angle>0</outer_angle>
        <falloff>0</falloff>
      </spot>
    </light>
    <model name='ground_plane'>
      <static>1</static>
      <link name='link'>
        <collision name='collision'>
          <geometry>
            <plane>
              <normal>0 0 1</normal>
              <size>100 100</size>
            </plane>
          </geometry>
          <surface>
            <contact>
              <collide_bitmask>65535</collide_bitmask>
              <ode/>
            </contact>
            <friction>
              <ode>
                <mu>100</mu>
                <mu2>50</mu2>
              </ode>
              <torsional>
                <ode/>
              </torsional>
            </friction>
            <bounce/>
          </surface>
          <max_contacts>10</max_contacts>
        </collision>
        <visual name='visual'>
          <cast_shadows>0</cast_shadows>
          <geometry>
            <plane>
              <normal>0 0 1</normal>
              <size>100 100</size>
            </plane>
          </geometry>
          <material>
            <script>
              <uri>file://media/materials/scripts/gazebo.material</uri>
              <name>Gazebo/Grey</name>
            </script>
          </material>
        </visual>
        <self_collide>0</self_collide>
        <enable_wind>0</enable_wind>
        <kinematic>0</kinematic>
      </link>
    </model>
    <gravity>0 0 -9.8</gravity>
    <magnetic_field>6e-06 2.3e-05 -4.2e-05</magnetic_field>
    <atmosphere type='adiabatic'/>
    <physics type='ode'>
      <max_step_size>0.001</max_step_size>
      <real_time_factor>1</real_time_factor>
      <real_time_update_rate>1000</real_time_update_rate>
    </physics>
    <scene>
      <ambient>0.4 0.4 0.4 1</ambient>
      <background>0.7 0.7 0.7 1</background>
      <shadows>1</shadows>
    </scene>
    <audio>
      <device>default</device>
    </audio>
    <wind/>
    <spherical_coordinates>
      <surface_model>EARTH_WGS84</surface_model>
      <latitude_deg>0</latitude_deg>
      <longitude_deg>0</longitude_deg>
      <elevation>0</elevation>
      <heading_deg>0</heading_deg>
    </spherical_coordinates>
    <model name='AdjTable'>
      <static>1</static>
      <link name='body'>
        <pose>0 0 0 0 -0 0</pose>
        <visual name='visual'>
          <geometry>
            <mesh>
              <uri>model://AdjTable/meshes/AdjTable.obj</uri>
            </mesh>
          </geometry>
        </visual>
        <collision name='collision'>
          <geometry>
            <mesh>
              <uri>model://AdjTable/meshes/AdjTable_Col.obj</uri>
            </mesh>
          </geometry>
          <max_contacts>10</max_contacts>
          <surface>
            <contact>
              <ode/>
            </contact>
            <bounce/>
            <friction>
              <torsional>
                <ode/>
              </torsional>
              <ode/>
            </friction>
          </surface>
        </collision>
        <self_collide>0</self_collide>
        <enable_wind>0</enable_wind>
        <kinematic>0</kinematic>
      </link>
      <pose>0.741472 -0.406521 0 0 -0 0</pose>
    </model>
    <model name='AdjTable_0'>
      <static>1</static>
      <link name='body'>
        <pose>0 0 0 0 -0 0</pose>
        <visual name='visual'>
          <geometry>
            <mesh>
              <uri>model://AdjTable/meshes/AdjTable.obj</uri>
            </mesh>
          </geometry>
        </visual>
        <collision name='collision'>
          <geometry>
            <mesh>
              <uri>model://AdjTable/meshes/AdjTable_Col.obj</uri>
            </mesh>
          </geometry>
          <max_contacts>10</max_contacts>
          <surface>
            <contact>
              <ode/>
            </contact>
            <bounce/>
            <friction>
              <torsional>
                <ode/>
              </torsional>
              <ode/>
            </friction>
          </surface>
        </collision>
        <self_collide>0</self_collide>
        <enable_wind>0</enable_wind>
        <kinematic>0</kinematic>
      </link>
      <pose>2.36041 -0.435259 0 0 -0 0</pose>
    </model>
    <model name='MonitorAndKeyboard'>
      <link name='body'>
        <pose>0 0 0 0 -0 0</pose>
        <visual name='visual_monitor'>
          <geometry>
            <mesh>
              <uri>model://MonitorAndKeyboard/meshes/monitor.obj</uri>
              <scale>0.2 0.2 0.2</scale>
            </mesh>
          </geometry>
          <pose>0 0 0 0 -0 0</pose>
        </visual>
        <collision name='collision_monitor'>
          <geometry>
            <mesh>
              <uri>model://MonitorAndKeyboard/meshes/monitor.obj</uri>
              <scale>0.2 0.2 0.2</scale>
            </mesh>
          </geometry>
          <pose>0 0 0 0 -0 0</pose>
          <max_contacts>10</max_contacts>
          <surface>
            <contact>
              <ode/>
            </contact>
            <bounce/>
            <friction>
              <torsional>
                <ode/>
              </torsional>
              <ode/>
            </friction>
          </surface>
        </collision>
        <visual name='visual_keyboard'>
          <geometry>
            <mesh>
              <uri>model://MonitorAndKeyboard/meshes/keyboard.obj</uri>
              <scale>0.2 0.2 0.2</scale>
            </mesh>
          </geometry>
          <pose>-0.27 0 0 0 -0 0</pose>
        </visual>
        <collision name='collision_keyboard'>
          <geometry>
            <mesh>
              <uri>model://MonitorAndKeyboard/meshes/keyboard.obj</uri>
              <scale>0.2 0.2 0.2</scale>
            </mesh>
          </geometry>
          <pose>-0.27 0 0 0 -0 0</pose>
          <max_contacts>10</max_contacts>
          <surface>
            <contact>
              <ode/>
            </contact>
            <bounce/>
            <friction>
              <torsional>
                <ode/>
              </torsional>
              <ode/>
            </friction>
          </surface>
        </collision>
        <self_collide>0</self_collide>
        <inertial>
          <pose>0 0 0 0 -0 0</pose>
          <inertia>
            <ixx>1</ixx>
            <ixy>0</ixy>
            <ixz>0</ixz>
            <iyy>1</iyy>
            <iyz>0</iyz>
            <izz>1</izz>
          </inertia>
          <mass>1</mass>
        </inertial>
        <enable_wind>0</enable_wind>
        <kinematic>0</kinematic>
      </link>
      <pose>1.08471 -1.42476 0 0 -0 0</pose>
    </model>
    <model name='MonitorAndKeyboard_clone'>
      <link name='body'>
        <pose>0 0 0 0 -0 0</pose>
        <visual name='visual_monitor'>
          <geometry>
            <mesh>
              <uri>model://MonitorAndKeyboard/meshes/monitor.obj</uri>
              <scale>0.2 0.2 0.2</scale>
            </mesh>
          </geometry>
          <pose>0 0 0 0 -0 0</pose>
        </visual>
        <collision name='collision_monitor'>
          <geometry>
            <mesh>
              <uri>model://MonitorAndKeyboard/meshes/monitor.obj</uri>
              <scale>0.2 0.2 0.2</scale>
            </mesh>
          </geometry>
          <pose>0 0 0 0 -0 0</pose>
          <max_contacts>10</max_contacts>
          <surface>
            <contact>
              <ode/>
            </contact>
            <bounce/>
            <friction>
              <torsional>
                <ode/>
              </torsional>
              <ode/>
            </friction>
          </surface>
        </collision>
        <visual name='visual_keyboard'>
          <geometry>
            <mesh>
              <uri>model://MonitorAndKeyboard/meshes/keyboard.obj</uri>
              <scale>0.2 0.2 0.2</scale>
            </mesh>
          </geometry>
          <pose>-0.27 0 0 0 -0 0</pose>
        </visual>
        <collision name='collision_keyboard'>
          <geometry>
            <mesh>
              <uri>model://MonitorAndKeyboard/meshes/keyboard.obj</uri>
              <scale>0.2 0.2 0.2</scale>
            </mesh>
          </geometry>
          <pose>-0.27 0 0 0 -0 0</pose>
          <max_contacts>10</max_contacts>
          <surface>
            <contact>
              <ode/>
            </contact>
            <bounce/>
            <friction>
              <torsional>
                <ode/>
              </torsional>
              <ode/>
            </friction>
          </surface>
        </collision>
        <self_collide>0</self_collide>
        <inertial>
          <pose>0 0 0 0 -0 0</pose>
          <inertia>
            <ixx>1</ixx>
            <ixy>0</ixy>
            <ixz>0</ixz>
            <iyy>1</iyy>
            <iyz>0</iyz>
            <izz>1</izz>
          </inertia>
          <mass>1</mass>
        </inertial>
        <enable_wind>0</enable_wind>
        <kinematic>0</kinematic>
      </link>
      <pose>1.91434 -0.197149 0.810564 -0 2e-06 1.57583</pose>
    </model>
    <model name='nanosaur'>
      <link name='base_link'>
        <inertial>
          <pose>0.007416 0 0.028711 0 -0 0</pose>
          <mass>0.17</mass>
          <inertia>
            <ixx>0.000128586</ixx>
            <ixy>2.5411e-21</ixy>
            <ixz>-1.37217e-05</ixz>
            <iyy>0.000314622</iyy>
            <iyz>0</iyz>
            <izz>0.000360215</izz>
          </inertia>
        </inertial>
        <collision name='base_link_fixed_joint_lump__cover_collision'>
          <pose>0.063 0 0.034 -1.57079 1.57079 3.14159</pose>
          <geometry>
            <cylinder>
              <length>0.07</length>
              <radius>0.028</radius>
            </cylinder>
          </geometry>
          <surface>
            <contact>
              <ode/>
            </contact>
            <friction>
              <ode/>
              <torsional>
                <ode/>
              </torsional>
            </friction>
            <bounce/>
          </surface>
          <max_contacts>10</max_contacts>
        </collision>
        <collision name='base_link_fixed_joint_lump__base_rear_collision_1'>
          <pose>0 0 0.02 0 -0 0</pose>
          <geometry>
            <box>
              <size>0.12 0.07 0.03</size>
            </box>
          </geometry>
          <surface>
            <contact>
              <ode/>
            </contact>
            <friction>
              <ode/>
              <torsional>
                <ode/>
              </torsional>
            </friction>
            <bounce/>
          </surface>
          <max_contacts>10</max_contacts>
        </collision>
        <visual name='base_link_fixed_joint_lump__base_front_visual'>
          <pose>0 0 0.03 0 -0 0</pose>
          <geometry>
            <mesh>
              <scale>0.001 0.001 0.001</scale>
              <uri>file:///home/user/nanosaur/install/nanosaur_description/share/nanosaur_description/meshes/base_front.stl</uri>
            </mesh>
          </geometry>
          <material>
            <ambient>0 0.5 0 1</ambient>
            <diffuse>0 0.5 0 1</diffuse>
            <specular>0 0.5 0 1</specular>
            <script>
              <name>Gazebo/Green</name>
              <uri>file://media/materials/scripts/gazebo.material</uri>
            </script>
          </material>
        </visual>
        <visual name='base_link_fixed_joint_lump__cover_visual_1'>
          <pose>0.06 0 0.004 0 -0 0</pose>
          <geometry>
            <mesh>
              <scale>0.001 0.001 0.001</scale>
              <uri>file:///home/user/nanosaur/install/nanosaur_description/share/nanosaur_description/meshes/cover-fe.stl</uri>
            </mesh>
          </geometry>
          <material>
            <ambient>0 0.5 0 1</ambient>
            <diffuse>0 0.5 0 1</diffuse>
            <specular>0 0.5 0 1</specular>
            <script>
              <name>Gazebo/Green</name>
              <uri>file://media/materials/scripts/gazebo.material</uri>
            </script>
          </material>
        </visual>
        <visual name='base_link_fixed_joint_lump__camera_board_visual_2'>
          <pose>0.072864 0 0.038798 0.087266 1e-06 -1.5708</pose>
          <geometry>
            <mesh>
              <scale>1 1 1</scale>
              <uri>file:///home/user/nanosaur/install/nanosaur_description/share/nanosaur_description/meshes/parts/fisheye_camera.dae</uri>
            </mesh>
          </geometry>
          <material>
            <ambient>0.2 0.2 0.2 1</ambient>
            <diffuse>0.2 0.2 0.2 1</diffuse>
            <specular>0.2 0.2 0.2 1</specular>
            <script>
              <name>Gazebo/Grey</name>
              <uri>file://media/materials/scripts/gazebo.material</uri>
            </script>
          </material>
        </visual>
        <visual name='base_link_fixed_joint_lump__camera_camera_link_visual_3'>
          <pose>0.0742 0 0.035 0 -0.087266 0</pose>
          <geometry>
            <box>
              <size>0.02 0.01 0.01</size>
            </box>
          </geometry>
        </visual>
        <visual name='base_link_fixed_joint_lump__display_left_visual_4'>
          <pose>0.036 0.0242 0.064 0.401425 1e-06 1.57079</pose>
          <geometry>
            <mesh>
              <scale>1 1 1</scale>
              <uri>file:///home/user/nanosaur/install/nanosaur_description/share/nanosaur_description/meshes/parts/OLED_Module.stl</uri>
            </mesh>
          </geometry>
          <material>
            <script>
              <name>Gazebo/Black</name>
              <uri>file://media/materials/scripts/gazebo.material</uri>
            </script>
          </material>
        </visual>
        <visual name='base_link_fixed_joint_lump__display_right_visual_5'>
          <pose>0.036 -0.0242 0.064 0.401425 1e-06 1.57079</pose>
          <geometry>
            <mesh>
              <scale>1 1 1</scale>
              <uri>file:///home/user/nanosaur/install/nanosaur_description/share/nanosaur_description/meshes/parts/OLED_Module.stl</uri>
            </mesh>
          </geometry>
          <material>
            <script>
              <name>Gazebo/Black</name>
              <uri>file://media/materials/scripts/gazebo.material</uri>
            </script>
          </material>
        </visual>
        <visual name='base_link_fixed_joint_lump__motor_board_visual_6'>
          <pose>0.055 0 0.035 0 0.95993 0</pose>
          <geometry>
            <mesh>
              <scale>1 1 1</scale>
              <uri>file:///home/user/nanosaur/install/nanosaur_description/share/nanosaur_description/meshes/parts/motor_board.stl</uri>
            </mesh>
          </geometry>
          <material>
            <ambient>0.2 0.2 0.2 1</ambient>
            <diffuse>0.2 0.2 0.2 1</diffuse>
            <specular>0.2 0.2 0.2 1</specular>
            <script>
              <name>Gazebo/DarkGrey</name>
              <uri>file://media/materials/scripts/gazebo.material</uri>
            </script>
          </material>
        </visual>
        <visual name='base_link_fixed_joint_lump__base_rear_visual_7'>
          <pose>0 0 0.03 0 -0 0</pose>
          <geometry>
            <mesh>
              <scale>0.001 0.001 0.001</scale>
              <uri>file:///home/user/nanosaur/install/nanosaur_description/share/nanosaur_description/meshes/base_rear.stl</uri>
            </mesh>
          </geometry>
          <material>
            <ambient>0 0.5 0 1</ambient>
            <diffuse>0 0.5 0 1</diffuse>
            <specular>0 0.5 0 1</specular>
            <script>
              <name>Gazebo/Green</name>
              <uri>file://media/materials/scripts/gazebo.material</uri>
            </script>
          </material>
        </visual>
        <visual name='base_link_fixed_joint_lump__NVIDIA_jetson_visual_8'>
          <pose>0.039 0.022 0.035 0 -0 3.14159</pose>
          <geometry>
            <mesh>
              <scale>1 1 1</scale>
              <uri>file:///home/user/nanosaur/install/nanosaur_description/share/nanosaur_description/meshes/parts/NVIDIA_jetson_nano_4gb.stl</uri>
            </mesh>
          </geometry>
          <material>
            <ambient>0.2 0.2 0.2 1</ambient>
            <diffuse>0.2 0.2 0.2 1</diffuse>
            <specular>0.2 0.2 0.2 1</specular>
            <script>
              <name>Gazebo/DarkGrey</name>
              <uri>file://media/materials/scripts/gazebo.material</uri>
            </script>
          </material>
        </visual>
        <visual name='base_link_fixed_joint_lump__flap_bottom_visual_9'>
          <pose>-0.0432 0 0.0475 0 -0 0</pose>
          <geometry>
            <mesh>
              <scale>0.001 0.001 0.001</scale>
              <uri>file:///home/user/nanosaur/install/nanosaur_description/share/nanosaur_description/meshes/flap_bottom.stl</uri>
            </mesh>
          </geometry>
          <material>
            <ambient>0 0.5 0 1</ambient>
            <diffuse>0 0.5 0 1</diffuse>
            <specular>0 0.5 0 1</specular>
            <script>
              <name>Gazebo/Green</name>
              <uri>file://media/materials/scripts/gazebo.material</uri>
            </script>
          </material>
        </visual>
        <visual name='base_link_fixed_joint_lump__board_expansion_visual_10'>
          <pose>-0.052 0.0005 0.047 0 -0 0</pose>
          <geometry>
            <mesh>
              <scale>1 1 1</scale>
              <uri>file:///home/user/nanosaur/install/nanosaur_description/share/nanosaur_description/meshes/parts/nanosaur-exp-board.stl</uri>
            </mesh>
          </geometry>
          <material>
            <ambient>0.5 0.5 0.5 1</ambient>
            <diffuse>0.5 0.5 0.5 1</diffuse>
            <specular>0.5 0.5 0.5 1</specular>
            <script>
              <name>Gazebo/DarkGrey</name>
              <uri>file://media/materials/scripts/gazebo.material</uri>
            </script>
          </material>
        </visual>
        <visual name='base_link_fixed_joint_lump__flap_top_visual_11'>
          <pose>-0.0432 0 0.0475 0 -0 0</pose>
          <geometry>
            <mesh>
              <scale>0.001 0.001 0.001</scale>
              <uri>file:///home/user/nanosaur/install/nanosaur_description/share/nanosaur_description/meshes/flap_top.stl</uri>
            </mesh>
          </geometry>
          <material>
            <ambient>0 0.5 0 1</ambient>
            <diffuse>0 0.5 0 1</diffuse>
            <specular>0 0.5 0 1</specular>
            <script>
              <name>Gazebo/Green</name>
              <uri>file://media/materials/scripts/gazebo.material</uri>
            </script>
          </material>
        </visual>
        <visual name='base_link_fixed_joint_lump__pb_holder_visual_12'>
          <pose>-0.0545 0 0.0239 0 -0 0</pose>
          <geometry>
            <mesh>
              <scale>0.001 0.001 0.001</scale>
              <uri>file:///home/user/nanosaur/install/nanosaur_description/share/nanosaur_description/meshes/pb_holder.stl</uri>
            </mesh>
          </geometry>
          <material>
            <ambient>0 0.5 0 1</ambient>
            <diffuse>0 0.5 0 1</diffuse>
            <specular>0 0.5 0 1</specular>
            <script>
              <name>Gazebo/Green</name>
              <uri>file://media/materials/scripts/gazebo.material</uri>
            </script>
          </material>
        </visual>
        <visual name='base_link_fixed_joint_lump__power_bank_visual_13'>
          <pose>0 0 0.0185 0 -0 3.14159</pose>
          <geometry>
            <mesh>
              <scale>1 1 1</scale>
              <uri>file:///home/user/nanosaur/install/nanosaur_description/share/nanosaur_description/meshes/parts/power_bank.stl</uri>
            </mesh>
          </geometry>
          <material>
            <ambient>0.2 0.2 0.2 1</ambient>
            <diffuse>0.2 0.2 0.2 1</diffuse>
            <specular>0.2 0.2 0.2 1</specular>
            <script>
              <name>Gazebo/DarkGrey</name>
              <uri>file://media/materials/scripts/gazebo.material</uri>
            </script>
          </material>
        </visual>
        <visual name='base_link_fixed_joint_lump__motor_left_visual_14'>
          <pose>0.053 0.012 0.015 1.57079 -1.57079 3.14159</pose>
          <geometry>
            <mesh>
              <scale>1 1 1</scale>
              <uri>file:///home/user/nanosaur/install/nanosaur_description/share/nanosaur_description/meshes/parts/Pololu-Micro-Metal-Gearmotor.stl</uri>
            </mesh>
          </geometry>
          <material>
            <ambient>0.9 0.7 0 1</ambient>
            <diffuse>0.9 0.7 0 1</diffuse>
            <specular>0.9 0.7 0 1</specular>
            <script>
              <name>Gazebo/Gold</name>
              <uri>file://media/materials/scripts/gazebo.material</uri>
            </script>
          </material>
        </visual>
        <visual name='base_link_fixed_joint_lump__track_left_visual_15'>
          <pose>0.004 0.043 0.015 0 -0 0</pose>
          <geometry>
            <mesh>
              <scale>0.001 0.001 0.001</scale>
              <uri>file:///home/user/nanosaur/install/nanosaur_description/share/nanosaur_description/meshes/track.stl</uri>
            </mesh>
          </geometry>
          <material>
            <ambient>0.01 0.01 0.01 1</ambient>
            <diffuse>0.01 0.01 0.01 1</diffuse>
            <specular>0.01 0.01 0.01 1</specular>
            <script>
              <name>Gazebo/Black</name>
              <uri>file://media/materials/scripts/gazebo.material</uri>
            </script>
          </material>
        </visual>
        <visual name='base_link_fixed_joint_lump__slider_left_visual_16'>
          <pose>0.004 0.051 0.015 -1.57079 0 0</pose>
          <geometry>
            <mesh>
              <scale>0.001 0.001 0.001</scale>
              <uri>file:///home/user/nanosaur/install/nanosaur_description/share/nanosaur_description/meshes/slider.stl</uri>
            </mesh>
          </geometry>
          <material>
            <ambient>0 0.5 0 1</ambient>
            <diffuse>0 0.5 0 1</diffuse>
            <specular>0 0.5 0 1</specular>
            <script>
              <name>Gazebo/Green</name>
              <uri>file://media/materials/scripts/gazebo.material</uri>
            </script>
          </material>
        </visual>
        <visual name='base_link_fixed_joint_lump__motor_right_visual_17'>
          <pose>0.053 -0.012 0.015 -1.57079 1.57079 3.14159</pose>
          <geometry>
            <mesh>
              <scale>1 1 1</scale>
              <uri>file:///home/user/nanosaur/install/nanosaur_description/share/nanosaur_description/meshes/parts/Pololu-Micro-Metal-Gearmotor.stl</uri>
            </mesh>
          </geometry>
          <material>
            <ambient>0.9 0.7 0 1</ambient>
            <diffuse>0.9 0.7 0 1</diffuse>
            <specular>0.9 0.7 0 1</specular>
            <script>
              <name>Gazebo/Gold</name>
              <uri>file://media/materials/scripts/gazebo.material</uri>
            </script>
          </material>
        </visual>
        <visual name='base_link_fixed_joint_lump__track_right_visual_18'>
          <pose>0.004 -0.043 0.015 3.14159 -0 0</pose>
          <geometry>
            <mesh>
              <scale>0.001 0.001 0.001</scale>
              <uri>file:///home/user/nanosaur/install/nanosaur_description/share/nanosaur_description/meshes/track.stl</uri>
            </mesh>
          </geometry>
          <material>
            <ambient>0.01 0.01 0.01 1</ambient>
            <diffuse>0.01 0.01 0.01 1</diffuse>
            <specular>0.01 0.01 0.01 1</specular>
            <script>
              <name>Gazebo/Black</name>
              <uri>file://media/materials/scripts/gazebo.material</uri>
            </script>
          </material>
        </visual>
        <visual name='base_link_fixed_joint_lump__slider_right_visual_19'>
          <pose>0.004 -0.051 0.015 1.57079 -0 0</pose>
          <geometry>
            <mesh>
              <scale>0.001 0.001 0.001</scale>
              <uri>file:///home/user/nanosaur/install/nanosaur_description/share/nanosaur_description/meshes/slider.stl</uri>
            </mesh>
          </geometry>
          <material>
            <ambient>0 0.5 0 1</ambient>
            <diffuse>0 0.5 0 1</diffuse>
            <specular>0 0.5 0 1</specular>
            <script>
              <name>Gazebo/Green</name>
              <uri>file://media/materials/scripts/gazebo.material</uri>
            </script>
          </material>
        </visual>
        <sensor name='camera' type='wideanglecamera'>
          <camera>
            <horizontal_fov>6.283</horizontal_fov>
            <image>
              <width>320</width>
              <height>240</height>
            </image>
            <clip>
              <near>0.1</near>
              <far>100</far>
            </clip>
            <lens>
              <type>custom</type>
              <custom_function>
                <c1>1.05</c1>
                <c2>4</c2>
                <f>1</f>
                <fun>tan</fun>
              </custom_function>
              <scale_to_hfov>1</scale_to_hfov>
              <cutoff_angle>3.1415</cutoff_angle>
              <env_texture_size>512</env_texture_size>
            </lens>
            <always_on>1</always_on>
            <update_rate>30</update_rate>
          </camera>
          <plugin name='camera_controller' filename='libgazebo_ros_camera.so'>
            <cameraName>camera</cameraName>
            <imageTopicName>image_raw</imageTopicName>
            <cameraInfoTopicName>camera_info</cameraInfoTopicName>
            <frameName>camera_camera_link_frame</frameName>
            <hackBaseline>0.07</hackBaseline>
          </plugin>
          <pose>0.094124 0 0.036743 0 -0.087266 0</pose>
        </sensor>
        <self_collide>0</self_collide>
        <enable_wind>0</enable_wind>
        <kinematic>0</kinematic>
      </link>
      <joint name='front_wheel_left_joint' type='revolute'>
        <pose relative_to='base_link'>0.053 0.043 0.015 -1.57079 0 0</pose>
        <parent>base_link</parent>
        <child>front_wheel_left</child>
        <axis>
          <xyz>0 0 1</xyz>
          <limit>
            <lower>-1e+16</lower>
            <upper>1e+16</upper>
          </limit>
          <dynamics>
            <spring_reference>0</spring_reference>
            <spring_stiffness>0</spring_stiffness>
          </dynamics>
        </axis>
      </joint>
      <link name='front_wheel_left'>
        <pose relative_to='front_wheel_left_joint'>0 0 0 0 -0 0</pose>
        <inertial>
          <pose>0 0 0 0 -0 0</pose>
          <mass>0.01</mass>
          <inertia>
            <ixx>1.66667e-07</ixx>
            <ixy>0</ixy>
            <ixz>0</ixz>
            <iyy>1.66667e-07</iyy>
            <iyz>0</iyz>
            <izz>1.66667e-07</izz>
          </inertia>
        </inertial>
        <collision name='front_wheel_left_collision'>
          <pose>0 0 0 0 -0 0</pose>
          <geometry>
            <cylinder>
              <length>0.015</length>
              <radius>0.015</radius>
            </cylinder>
          </geometry>
          <surface>
            <contact>
              <ode>
                <kp>1e+07</kp>
                <kd>1e+07</kd>
              </ode>
            </contact>
            <friction>
              <ode>
                <mu>0</mu>
                <mu2>0</mu2>
              </ode>
              <torsional>
                <ode/>
              </torsional>
            </friction>
            <bounce/>
          </surface>
          <max_contacts>10</max_contacts>
        </collision>
        <visual name='front_wheel_left_visual'>
          <pose>0 0 0 0 -0 0</pose>
          <geometry>
            <mesh>
              <scale>0.001 0.001 0.001</scale>
              <uri>file:///home/user/nanosaur/install/nanosaur_description/share/nanosaur_description/meshes/wheel.stl</uri>
            </mesh>
          </geometry>
          <material>
            <ambient>0 0.5 0 1</ambient>
            <diffuse>0 0.5 0 1</diffuse>
            <specular>0 0.5 0 1</specular>
            <script>
              <name>Gazebo/Green</name>
              <uri>file://media/materials/scripts/gazebo.material</uri>
            </script>
          </material>
        </visual>
        <self_collide>0</self_collide>
        <enable_wind>0</enable_wind>
        <kinematic>0</kinematic>
      </link>
      <joint name='wheel_left_joint' type='revolute'>
        <pose relative_to='base_link'>-0.046 0.043 0.015 -1.57079 0 0</pose>
        <parent>base_link</parent>
        <child>wheel_left</child>
        <axis>
          <xyz>0 0 1</xyz>
          <limit>
            <lower>-1e+16</lower>
            <upper>1e+16</upper>
          </limit>
          <dynamics>
            <spring_reference>0</spring_reference>
            <spring_stiffness>0</spring_stiffness>
          </dynamics>
        </axis>
      </joint>
      <link name='wheel_left'>
        <pose relative_to='wheel_left_joint'>0 0 0 0 -0 0</pose>
        <inertial>
          <pose>0 0 0 0 -0 0</pose>
          <mass>0.01</mass>
          <inertia>
            <ixx>1.66667e-07</ixx>
            <ixy>0</ixy>
            <ixz>0</ixz>
            <iyy>1.66667e-07</iyy>
            <iyz>0</iyz>
            <izz>1.66667e-07</izz>
          </inertia>
        </inertial>
        <collision name='wheel_left_collision'>
          <pose>0 0 0 0 -0 0</pose>
          <geometry>
            <cylinder>
              <length>0.015</length>
              <radius>0.015</radius>
            </cylinder>
          </geometry>
          <surface>
            <contact>
              <ode>
                <kp>1e+07</kp>
                <kd>1e+07</kd>
              </ode>
            </contact>
            <friction>
              <ode>
                <mu>0</mu>
                <mu2>0</mu2>
              </ode>
              <torsional>
                <ode/>
              </torsional>
            </friction>
            <bounce/>
          </surface>
          <max_contacts>10</max_contacts>
        </collision>
        <visual name='wheel_left_visual'>
          <pose>0 0 0 0 -0 0</pose>
          <geometry>
            <mesh>
              <scale>0.001 0.001 0.001</scale>
              <uri>file:///home/user/nanosaur/install/nanosaur_description/share/nanosaur_description/meshes/wheel.stl</uri>
            </mesh>
          </geometry>
          <material>
            <ambient>0.5 0 0 1</ambient>
            <diffuse>0.5 0 0 1</diffuse>
            <specular>0.5 0 0 1</specular>
            <script>
              <name>Gazebo/Red</name>
              <uri>file://media/materials/scripts/gazebo.material</uri>
            </script>
          </material>
        </visual>
        <self_collide>0</self_collide>
        <enable_wind>0</enable_wind>
        <kinematic>0</kinematic>
      </link>
      <joint name='front_wheel_right_joint' type='revolute'>
        <pose relative_to='base_link'>0.053 -0.043 0.015 1.57079 -0 0</pose>
        <parent>base_link</parent>
        <child>front_wheel_right</child>
        <axis>
          <xyz>0 0 -1</xyz>
          <limit>
            <lower>-1e+16</lower>
            <upper>1e+16</upper>
          </limit>
          <dynamics>
            <spring_reference>0</spring_reference>
            <spring_stiffness>0</spring_stiffness>
          </dynamics>
        </axis>
      </joint>
      <link name='front_wheel_right'>
        <pose relative_to='front_wheel_right_joint'>0 0 0 0 -0 0</pose>
        <inertial>
          <pose>0 0 0 0 -0 0</pose>
          <mass>0.01</mass>
          <inertia>
            <ixx>1.66667e-07</ixx>
            <ixy>0</ixy>
            <ixz>0</ixz>
            <iyy>1.66667e-07</iyy>
            <iyz>0</iyz>
            <izz>1.66667e-07</izz>
          </inertia>
        </inertial>
        <collision name='front_wheel_right_collision'>
          <pose>0 0 0 0 -0 0</pose>
          <geometry>
            <cylinder>
              <length>0.015</length>
              <radius>0.015</radius>
            </cylinder>
          </geometry>
          <surface>
            <contact>
              <ode>
                <kp>1e+07</kp>
                <kd>1e+07</kd>
              </ode>
            </contact>
            <friction>
              <ode>
                <mu>0</mu>
                <mu2>0</mu2>
              </ode>
              <torsional>
                <ode/>
              </torsional>
            </friction>
            <bounce/>
          </surface>
          <max_contacts>10</max_contacts>
        </collision>
        <visual name='front_wheel_right_visual'>
          <pose>0 0 0 0 -0 0</pose>
          <geometry>
            <mesh>
              <scale>0.001 0.001 0.001</scale>
              <uri>file:///home/user/nanosaur/install/nanosaur_description/share/nanosaur_description/meshes/wheel.stl</uri>
            </mesh>
          </geometry>
          <material>
            <ambient>0 0.5 0 1</ambient>
            <diffuse>0 0.5 0 1</diffuse>
            <specular>0 0.5 0 1</specular>
            <script>
              <name>Gazebo/Green</name>
              <uri>file://media/materials/scripts/gazebo.material</uri>
            </script>
          </material>
        </visual>
        <self_collide>0</self_collide>
        <enable_wind>0</enable_wind>
        <kinematic>0</kinematic>
      </link>
      <joint name='wheel_right_joint' type='revolute'>
        <pose relative_to='base_link'>-0.046 -0.043 0.015 1.57079 -0 0</pose>
        <parent>base_link</parent>
        <child>wheel_right</child>
        <axis>
          <xyz>0 0 -1</xyz>
          <limit>
            <lower>-1e+16</lower>
            <upper>1e+16</upper>
          </limit>
          <dynamics>
            <spring_reference>0</spring_reference>
            <spring_stiffness>0</spring_stiffness>
          </dynamics>
        </axis>
      </joint>
      <link name='wheel_right'>
        <pose relative_to='wheel_right_joint'>0 0 0 0 -0 0</pose>
        <inertial>
          <pose>0 0 0 0 -0 0</pose>
          <mass>0.01</mass>
          <inertia>
            <ixx>1.66667e-07</ixx>
            <ixy>0</ixy>
            <ixz>0</ixz>
            <iyy>1.66667e-07</iyy>
            <iyz>0</iyz>
            <izz>1.66667e-07</izz>
          </inertia>
        </inertial>
        <collision name='wheel_right_collision'>
          <pose>0 0 0 0 -0 0</pose>
          <geometry>
            <cylinder>
              <length>0.015</length>
              <radius>0.015</radius>
            </cylinder>
          </geometry>
          <surface>
            <contact>
              <ode>
                <kp>1e+07</kp>
                <kd>1e+07</kd>
              </ode>
            </contact>
            <friction>
              <ode>
                <mu>0</mu>
                <mu2>0</mu2>
              </ode>
              <torsional>
                <ode/>
              </torsional>
            </friction>
            <bounce/>
          </surface>
          <max_contacts>10</max_contacts>
        </collision>
        <visual name='wheel_right_visual'>
          <pose>0 0 0 0 -0 0</pose>
          <geometry>
            <mesh>
              <scale>0.001 0.001 0.001</scale>
              <uri>file:///home/user/nanosaur/install/nanosaur_description/share/nanosaur_description/meshes/wheel.stl</uri>
            </mesh>
          </geometry>
          <material>
            <ambient>0.5 0 0 1</ambient>
            <diffuse>0.5 0 0 1</diffuse>
            <specular>0.5 0 0 1</specular>
            <script>
              <name>Gazebo/Red</name>
              <uri>file://media/materials/scripts/gazebo.material</uri>
            </script>
          </material>
        </visual>
        <self_collide>0</self_collide>
        <enable_wind>0</enable_wind>
        <kinematic>0</kinematic>
      </link>
      <joint name='sprocket_left_joint' type='revolute'>
        <pose relative_to='base_link'>0 0.043 0.015 -1.57079 0 0</pose>
        <parent>base_link</parent>
        <child>sprocket_left</child>
        <axis>
          <xyz>0 0 1</xyz>
          <limit>
            <lower>-1e+16</lower>
            <upper>1e+16</upper>
          </limit>
          <dynamics>
            <spring_reference>0</spring_reference>
            <spring_stiffness>0</spring_stiffness>
          </dynamics>
        </axis>
      </joint>
      <link name='sprocket_left'>
        <pose relative_to='sprocket_left_joint'>0 0 0 0 -0 0</pose>
        <inertial>
          <pose>0 0 0 0 -0 0</pose>
          <mass>0.01</mass>
          <inertia>
            <ixx>1.66667e-07</ixx>
            <ixy>0</ixy>
            <ixz>0</ixz>
            <iyy>1.66667e-07</iyy>
            <iyz>0</iyz>
            <izz>1.66667e-07</izz>
          </inertia>
        </inertial>
        <collision name='sprocket_left_collision'>
          <pose>0 0 0 0 -0 0</pose>
          <geometry>
            <cylinder>
              <length>0.015</length>
              <radius>0.015</radius>
            </cylinder>
          </geometry>
          <surface>
            <contact>
              <ode>
                <kp>1e+07</kp>
                <kd>1e+07</kd>
              </ode>
            </contact>
            <friction>
              <ode>
                <mu>1e+07</mu>
                <mu2>1e+07</mu2>
              </ode>
              <torsional>
                <ode/>
              </torsional>
            </friction>
            <bounce/>
          </surface>
          <max_contacts>10</max_contacts>
        </collision>
        <visual name='sprocket_left_visual'>
          <pose>0 0 0 0 -0 0</pose>
          <geometry>
            <mesh>
              <scale>0.001 0.001 0.001</scale>
              <uri>file:///home/user/nanosaur/install/nanosaur_description/share/nanosaur_description/meshes/sprocket.stl</uri>
            </mesh>
          </geometry>
          <material>
            <ambient>0 0 0.5 1</ambient>
            <diffuse>0 0 0.5 1</diffuse>
            <specular>0 0 0.5 1</specular>
            <script>
              <name>Gazebo/Blue</name>
              <uri>file://media/materials/scripts/gazebo.material</uri>
            </script>
          </material>
        </visual>
        <self_collide>0</self_collide>
        <enable_wind>0</enable_wind>
        <kinematic>0</kinematic>
      </link>
      <joint name='sprocket_right_joint' type='revolute'>
        <pose relative_to='base_link'>0 -0.043 0.015 1.57079 -0 0</pose>
        <parent>base_link</parent>
        <child>sprocket_right</child>
        <axis>
          <xyz>0 0 -1</xyz>
          <limit>
            <lower>-1e+16</lower>
            <upper>1e+16</upper>
          </limit>
          <dynamics>
            <spring_reference>0</spring_reference>
            <spring_stiffness>0</spring_stiffness>
          </dynamics>
        </axis>
      </joint>
      <link name='sprocket_right'>
        <pose relative_to='sprocket_right_joint'>0 0 0 0 -0 0</pose>
        <inertial>
          <pose>0 0 0 0 -0 0</pose>
          <mass>0.01</mass>
          <inertia>
            <ixx>1.66667e-07</ixx>
            <ixy>0</ixy>
            <ixz>0</ixz>
            <iyy>1.66667e-07</iyy>
            <iyz>0</iyz>
            <izz>1.66667e-07</izz>
          </inertia>
        </inertial>
        <collision name='sprocket_right_collision'>
          <pose>0 0 0 0 -0 0</pose>
          <geometry>
            <cylinder>
              <length>0.015</length>
              <radius>0.015</radius>
            </cylinder>
          </geometry>
          <surface>
            <contact>
              <ode>
                <kp>1e+07</kp>
                <kd>1e+07</kd>
              </ode>
            </contact>
            <friction>
              <ode>
                <mu>1e+07</mu>
                <mu2>1e+07</mu2>
              </ode>
              <torsional>
                <ode/>
              </torsional>
            </friction>
            <bounce/>
          </surface>
          <max_contacts>10</max_contacts>
        </collision>
        <visual name='sprocket_right_visual'>
          <pose>0 0 0 0 -0 0</pose>
          <geometry>
            <mesh>
              <scale>0.001 0.001 0.001</scale>
              <uri>file:///home/user/nanosaur/install/nanosaur_description/share/nanosaur_description/meshes/sprocket.stl</uri>
            </mesh>
          </geometry>
          <material>
            <ambient>0 0 0.5 1</ambient>
            <diffuse>0 0 0.5 1</diffuse>
            <specular>0 0 0.5 1</specular>
            <script>
              <name>Gazebo/Blue</name>
              <uri>file://media/materials/scripts/gazebo.material</uri>
            </script>
          </material>
        </visual>
        <self_collide>0</self_collide>
        <enable_wind>0</enable_wind>
        <kinematic>0</kinematic>
      </link>
      <static>0</static>
      <plugin name='skid_steer_drive_controller' filename='libgazebo_ros_diff_drive.so'>
        <ros>
          <namespace>/nanosaur</namespace>
          <argument>--ros-args --remap /cmd_vel:=cmd_vel</argument>
          <argument>--ros-args --remap /odom:=odom</argument>
        </ros>
        <update_rate>100.0</update_rate>
        <num_wheel_pairs>2</num_wheel_pairs>
        <left_joint>sprocket_left_joint</left_joint>
        <left_joint>wheel_left_joint</left_joint>
        <right_joint>sprocket_right_joint</right_joint>
        <right_joint>wheel_right_joint</right_joint>
        <wheel_separation>0.4</wheel_separation>
        <wheel_diameter>0.03</wheel_diameter>
        <wheel_acceleration>0.0</wheel_acceleration>
        <max_wheel_torque>15</max_wheel_torque>
        <odometry_frame>odom</odometry_frame>
        <robot_base_frame>base_link</robot_base_frame>
        <publish_odom>1</publish_odom>
        <publish_odom_tf>0</publish_odom_tf>
        <publish_wheel_tf>1</publish_wheel_tf>
        <odometry_source>1</odometry_source>
        <publis_wheel_joint_state>0</publis_wheel_joint_state>
      </plugin>
      <pose>0.956851 -0.346093 0 0 -0 0</pose>
    </model>
    <model name='OfficeChairBlack'>
      <static>1</static>
      <link name='body'>
        <pose>0 0 0 0 -0 0</pose>
        <visual name='visual'>
          <geometry>
            <mesh>
              <uri>model://OfficeChairBlack/meshes/OfficeChairBlack.obj</uri>
            </mesh>
          </geometry>
        </visual>
        <collision name='collision'>
          <geometry>
            <mesh>
              <uri>model://OfficeChairBlack/meshes/OfficeChairBlack_Col.obj</uri>
            </mesh>
          </geometry>
          <max_contacts>10</max_contacts>
          <surface>
            <contact>
              <ode/>
            </contact>
            <bounce/>
            <friction>
              <torsional>
                <ode/>
              </torsional>
              <ode/>
            </friction>
          </surface>
        </collision>
        <self_collide>0</self_collide>
        <enable_wind>0</enable_wind>
        <kinematic>0</kinematic>
      </link>
      <pose>0.887805 -1.55623 0 0 -0 0</pose>
    </model>
    <model name='OfficeChairBlack_clone'>
      <static>1</static>
      <link name='body'>
        <pose>0 0 0 0 -0 0</pose>
        <visual name='visual'>
          <geometry>
            <mesh>
              <uri>model://OfficeChairBlack/meshes/OfficeChairBlack.obj</uri>
            </mesh>
          </geometry>
        </visual>
        <collision name='collision'>
          <geometry>
            <mesh>
              <uri>model://OfficeChairBlack/meshes/OfficeChairBlack_Col.obj</uri>
            </mesh>
          </geometry>
          <max_contacts>10</max_contacts>
          <surface>
            <contact>
              <ode/>
            </contact>
            <bounce/>
            <friction>
              <torsional>
                <ode/>
              </torsional>
              <ode/>
            </friction>
          </surface>
        </collision>
        <self_collide>0</self_collide>
        <enable_wind>0</enable_wind>
        <kinematic>0</kinematic>
      </link>
      <pose>2.39106 -1.07463 0 0 0 -3.13921</pose>
    </model>
    <model name='OfficeChairBlue'>
      <static>1</static>
      <link name='body'>
        <pose>0 0 0 0 -0 0</pose>
        <visual name='visual'>
          <geometry>
            <mesh>
              <uri>model://Drawer/meshes/Drawer.obj</uri>
            </mesh>
          </geometry>
        </visual>
        <collision name='collision'>
          <geometry>
            <mesh>
              <uri>model://Drawer/meshes/Drawer.obj</uri>
            </mesh>
          </geometry>
          <max_contacts>10</max_contacts>
          <surface>
            <contact>
              <ode/>
            </contact>
            <bounce/>
            <friction>
              <torsional>
                <ode/>
              </torsional>
              <ode/>
            </friction>
          </surface>
        </collision>
        <self_collide>0</self_collide>
        <enable_wind>0</enable_wind>
        <kinematic>0</kinematic>
      </link>
      <pose>0.319796 -0.495731 0 0 -0 0</pose>
    </model>
    <model name='OfficeChairBlue_0'>
      <static>1</static>
      <link name='body'>
        <pose>0 0 0 0 -0 0</pose>
        <visual name='visual'>
          <geometry>
            <mesh>
              <uri>model://Drawer/meshes/Drawer.obj</uri>
            </mesh>
          </geometry>
        </visual>
        <collision name='collision'>
          <geometry>
            <mesh>
              <uri>model://Drawer/meshes/Drawer.obj</uri>
            </mesh>
          </geometry>
          <max_contacts>10</max_contacts>
          <surface>
            <contact>
              <ode/>
            </contact>
            <bounce/>
            <friction>
              <torsional>
                <ode/>
              </torsional>
              <ode/>
            </friction>
          </surface>
        </collision>
        <self_collide>0</self_collide>
        <enable_wind>0</enable_wind>
        <kinematic>0</kinematic>
      </link>
      <pose>1.94283 -0.449062 0 0 -0 0</pose>
    </model>
    <state world_name='default'>
      <sim_time>2235 959000000</sim_time>
      <real_time>2480 521621975</real_time>
      <wall_time>1683528120 465971512</wall_time>
      <iterations>2235959</iterations>
      <model name='AdjTable'>
        <pose>0.741472 -0.406521 0 0 -0 0</pose>
        <scale>1 1 1</scale>
        <link name='body'>
          <pose>0.741472 -0.406521 0 0 -0 0</pose>
          <velocity>0 0 0 0 -0 0</velocity>
          <acceleration>0 0 0 0 -0 0</acceleration>
          <wrench>0 0 0 0 -0 0</wrench>
        </link>
      </model>
      <model name='AdjTable_0'>
        <pose>2.3811 -0.3745 0 0 -0 0</pose>
        <scale>1 1 1</scale>
        <link name='body'>
          <pose>2.3811 -0.3745 0 0 -0 0</pose>
          <velocity>0 0 0 0 -0 0</velocity>
          <acceleration>0 0 0 0 -0 0</acceleration>
          <wrench>0 0 0 0 -0 0</wrench>
        </link>
      </model>
      <model name='MonitorAndKeyboard'>
        <pose>0.356022 -0.208837 0.810564 -1e-06 2e-06 1.57583</pose>
        <scale>1 1 1</scale>
        <link name='body'>
          <pose>0.356022 -0.208837 0.810564 -1e-06 2e-06 1.57583</pose>
          <velocity>0 0 0 0 -0 0</velocity>
          <acceleration>0 -0 -0.107333 -0.004577 -0.015034 0</acceleration>
          <wrench>0 -0 -0.107333 0 -0 0</wrench>
        </link>
      </model>
      <model name='MonitorAndKeyboard_clone'>
        <pose>1.91434 -0.197149 0.810555 0 4e-06 1.57583</pose>
        <scale>1 1 1</scale>
        <link name='body'>
          <pose>1.91434 -0.197149 0.810555 0 4e-06 1.57583</pose>
          <velocity>0 0 0 0 -0 0</velocity>
          <acceleration>0 0 -9.8 0 -0 0</acceleration>
          <wrench>0 0 -9.8 0 -0 0</wrench>
        </link>
      </model>
      <model name='OfficeChairBlack'>
        <pose>0.886683 -1.086 0 0 0 -3.13921</pose>
        <scale>1 1 1</scale>
        <link name='body'>
          <pose>0.886683 -1.086 0 0 0 -3.13921</pose>
          <velocity>0 0 0 0 -0 0</velocity>
          <acceleration>0 0 0 0 -0 0</acceleration>
          <wrench>0 0 0 0 -0 0</wrench>
        </link>
      </model>
      <model name='OfficeChairBlack_clone'>
        <pose>2.39106 -1.07463 0 0 0 -3.13921</pose>
        <scale>1 1 1</scale>
        <link name='body'>
          <pose>2.39106 -1.07463 0 0 0 -3.13921</pose>
          <velocity>0 0 0 0 -0 0</velocity>
          <acceleration>0 0 0 0 -0 0</acceleration>
          <wrench>0 0 0 0 -0 0</wrench>
        </link>
      </model>
      <model name='OfficeChairBlue'>
        <pose>0.319796 -0.495731 0 0 -0 0</pose>
        <scale>1 1 1</scale>
        <link name='body'>
          <pose>0.319796 -0.495731 0 0 -0 0</pose>
          <velocity>0 0 0 0 -0 0</velocity>
          <acceleration>0 0 0 0 -0 0</acceleration>
          <wrench>0 0 0 0 -0 0</wrench>
        </link>
      </model>
      <model name='OfficeChairBlue_0'>
        <pose>1.94283 -0.449062 0 0 -0 0</pose>
        <scale>1 1 1</scale>
        <link name='body'>
          <pose>1.94283 -0.449062 0 0 -0 0</pose>
          <velocity>0 0 0 0 -0 0</velocity>
          <acceleration>0 0 0 0 -0 0</acceleration>
          <wrench>0 0 0 0 -0 0</wrench>
        </link>
      </model>
      <model name='ground_plane'>
        <pose>0 0 0 0 -0 0</pose>
        <scale>1 1 1</scale>
        <link name='link'>
          <pose>0 0 0 0 -0 0</pose>
          <velocity>0 0 0 0 -0 0</velocity>
          <acceleration>0 0 0 0 -0 0</acceleration>
          <wrench>0 0 0 0 -0 0</wrench>
        </link>
      </model>
      <model name='nanosaur'>
        <pose>0.93635 -0.254535 0.810564 0 1e-06 -0.984681</pose>
        <scale>1 1 1</scale>
        <link name='base_link'>
          <pose>0.93635 -0.254535 0.810564 0 1e-06 -0.984681</pose>
          <velocity>2.1e-05 -2.1e-05 -5e-06 6.6e-05 -8.9e-05 0.000539</velocity>
          <acceleration>0.001585 0.002048 -0.008226 -0.288096 0.69407 -0.047151</acceleration>
          <wrench>0.000269 0.000348 -0.001398 0 -0 0</wrench>
        </link>
        <link name='front_wheel_left'>
          <pose>1.00149 -0.274904 0.825564 -1.56925 -1.41395 -0.986213</pose>
          <velocity>3.2e-05 1.4e-05 -3.7e-05 -0.015307 -0.027593 0.000532</velocity>
          <acceleration>0.003071 0.000493 -0.139976 2.09222 -0.202874 -0.027111</acceleration>
          <wrench>3.1e-05 5e-06 -0.0014 0 -0 0</wrench>
        </link>
        <link name='front_wheel_right'>
          <pose>0.929842 -0.322473 0.825564 -1.5705 -0.609148 2.15674</pose>
          <velocity>5.7e-05 -2.6e-05 4.9e-05 0.00691 -0.021131 0.000547</velocity>
          <acceleration>0.002397 0.000889 0.083274 2.34575 -0.507433 -0.008073</acceleration>
          <wrench>2.4e-05 9e-06 0.000833 0 -0 0</wrench>
        </link>
        <link name='sprocket_left'>
          <pose>0.972173 -0.23075 0.825564 1.57082 -0.817079 2.1569</pose>
          <velocity>8e-06 -3e-06 0 2.8e-05 0.000404 0.000556</velocity>
          <acceleration>0.004301 0.00124 7.2e-05 -0.091117 0.281192 0.030585</acceleration>
          <wrench>4.3e-05 1.2e-05 1e-06 0 -0 0</wrench>
        </link>
        <link name='sprocket_right'>
          <pose>0.900527 -0.278319 0.825564 -1.57081 0.41202 2.1569</pose>
          <velocity>3.4e-05 -4.1e-05 -0 0.002885 0.002339 0.00052</velocity>
          <acceleration>0.004385 0.001918 -0.000365 -0.136727 0.286622 -0.032285</acceleration>
          <wrench>4.4e-05 1.9e-05 -4e-06 0 -0 0</wrench>
        </link>
        <link name='wheel_left'>
          <pose>0.946729 -0.192428 0.825564 -1.56388 1.54056 -0.977771</pose>
          <velocity>-1.3e-05 -1.6e-05 -3.1e-05 0.007109 -0.010786 0.000545</velocity>
          <acceleration>0.003822 0.00117 -0.000566 0.500985 -0.927879 -0.008846</acceleration>
          <wrench>3.8e-05 1.2e-05 -6e-06 0 -0 0</wrench>
        </link>
        <link name='wheel_right'>
          <pose>0.875083 -0.239997 0.825564 1.5705 0.702171 -0.984873</pose>
          <velocity>1.2e-05 -5.6e-05 -3e-05 -0.00815 0.01222 0.000542</velocity>
          <acceleration>0.003845 0.001402 0.001769 -0.811995 1.02607 -0.009582</acceleration>
          <wrench>3.8e-05 1.4e-05 1.8e-05 0 -0 0</wrench>
        </link>
      </model>
      <light name='sun'>
        <pose>0 0 10 0 -0 0</pose>
      </light>
    </state>
    <gui fullscreen='0'>
      <camera name='user_camera'>
        <pose>1.10209 -1.55204 2.13967 -0 1.10313 1.29407</pose>
        <view_controller>orbit</view_controller>
        <projection_type>perspective</projection_type>
      </camera>
    </gui>
  </world>
</sdf>
